2024-10-03 18:14:42.036332 - Starting the results2SQL script...
Both excel files from today found, inserting to database.
Results data inserted successfully.
last_results data inserted successfully.
Number of rows inserted into 'fundamentals': 2
2024-10-16 21:30:01.629856 - Starting the results2SQL script...
Both excel files from today found, inserting to database.
Results data inserted successfully.
last_results data inserted successfully.
Number of rows inserted into 'fundamentals': 233
2024-10-16 21:51:18.889940 - Starting the results2SQL script...
Both excel files from today found, inserting to database.
Results data inserted successfully.
last_results data inserted successfully.
Number of rows inserted into 'fundamentals': 2
/Users/Roho11/Documents/GitHub/DividendGrowthPicks/dividendStocks.py:83: UserWarning: Pandas requires version '1.4.3' or newer of 'xlsxwriter' (version '1.3.8' currently installed).
  df.to_excel(DSDfile)
/Users/Roho11/Documents/GitHub/DividendGrowthPicks/dividendStocks.py:93: SettingWithCopyWarning: 
A value is trying to be set on a copy of a slice from a DataFrame.
Try using .loc[row_indexer,col_indexer] = value instead

See the caveats in the documentation: https://pandas.pydata.org/pandas-docs/stable/user_guide/indexing.html#returning-a-view-versus-a-copy
  filtered_df[['freeCashFlowPayout', 'freeCashFlow', 'shareNum']] = filtered_df.apply(add_free_cash_flow, axis=1).apply(pd.Series)
/Users/Roho11/Documents/GitHub/DividendGrowthPicks/dividendStocks.py:93: SettingWithCopyWarning: 
A value is trying to be set on a copy of a slice from a DataFrame.
Try using .loc[row_indexer,col_indexer] = value instead

See the caveats in the documentation: https://pandas.pydata.org/pandas-docs/stable/user_guide/indexing.html#returning-a-view-versus-a-copy
  filtered_df[['freeCashFlowPayout', 'freeCashFlow', 'shareNum']] = filtered_df.apply(add_free_cash_flow, axis=1).apply(pd.Series)
/Users/Roho11/Documents/GitHub/DividendGrowthPicks/dividendStocks.py:93: SettingWithCopyWarning: 
A value is trying to be set on a copy of a slice from a DataFrame.
Try using .loc[row_indexer,col_indexer] = value instead

See the caveats in the documentation: https://pandas.pydata.org/pandas-docs/stable/user_guide/indexing.html#returning-a-view-versus-a-copy
  filtered_df[['freeCashFlowPayout', 'freeCashFlow', 'shareNum']] = filtered_df.apply(add_free_cash_flow, axis=1).apply(pd.Series)
/Users/Roho11/Documents/GitHub/DividendGrowthPicks/dividendStocks.py:167: UserWarning: Pandas requires version '1.4.3' or newer of 'xlsxwriter' (version '1.3.8' currently installed).
  sorted_data.to_excel(output_file_path, index=False)
Email sent successfully to kosirok@gmail.com
File '/Users/Roho11/Documents/GitHub/DividendGrowthPicks/DivStocks_tweet.html' deleted successfully.
Inflation data for Sep: 2.44%
Inflation data for Sep: 14.94%
Inflation data for Sep: 22.8%
Traceback (most recent call last):
  File "/Users/Roho11/opt/anaconda3/lib/python3.8/site-packages/urllib3/connectionpool.py", line 670, in urlopen
    httplib_response = self._make_request(
  File "/Users/Roho11/opt/anaconda3/lib/python3.8/site-packages/urllib3/connectionpool.py", line 426, in _make_request
    six.raise_from(e, None)
  File "<string>", line 3, in raise_from
  File "/Users/Roho11/opt/anaconda3/lib/python3.8/site-packages/urllib3/connectionpool.py", line 421, in _make_request
    httplib_response = conn.getresponse()
  File "/Users/Roho11/opt/anaconda3/lib/python3.8/http/client.py", line 1347, in getresponse
    response.begin()
  File "/Users/Roho11/opt/anaconda3/lib/python3.8/http/client.py", line 307, in begin
    version, status, reason = self._read_status()
  File "/Users/Roho11/opt/anaconda3/lib/python3.8/http/client.py", line 276, in _read_status
    raise RemoteDisconnected("Remote end closed connection without"
http.client.RemoteDisconnected: Remote end closed connection without response

During handling of the above exception, another exception occurred:

Traceback (most recent call last):
  File "/Users/Roho11/opt/anaconda3/lib/python3.8/site-packages/requests/adapters.py", line 439, in send
    resp = conn.urlopen(
  File "/Users/Roho11/opt/anaconda3/lib/python3.8/site-packages/urllib3/connectionpool.py", line 726, in urlopen
    retries = retries.increment(
  File "/Users/Roho11/opt/anaconda3/lib/python3.8/site-packages/urllib3/util/retry.py", line 410, in increment
    raise six.reraise(type(error), error, _stacktrace)
  File "/Users/Roho11/opt/anaconda3/lib/python3.8/site-packages/urllib3/packages/six.py", line 734, in reraise
    raise value.with_traceback(tb)
  File "/Users/Roho11/opt/anaconda3/lib/python3.8/site-packages/urllib3/connectionpool.py", line 670, in urlopen
    httplib_response = self._make_request(
  File "/Users/Roho11/opt/anaconda3/lib/python3.8/site-packages/urllib3/connectionpool.py", line 426, in _make_request
    six.raise_from(e, None)
  File "<string>", line 3, in raise_from
  File "/Users/Roho11/opt/anaconda3/lib/python3.8/site-packages/urllib3/connectionpool.py", line 421, in _make_request
    httplib_response = conn.getresponse()
  File "/Users/Roho11/opt/anaconda3/lib/python3.8/http/client.py", line 1347, in getresponse
    response.begin()
  File "/Users/Roho11/opt/anaconda3/lib/python3.8/http/client.py", line 307, in begin
    version, status, reason = self._read_status()
  File "/Users/Roho11/opt/anaconda3/lib/python3.8/http/client.py", line 276, in _read_status
    raise RemoteDisconnected("Remote end closed connection without"
urllib3.exceptions.ProtocolError: ('Connection aborted.', RemoteDisconnected('Remote end closed connection without response'))

During handling of the above exception, another exception occurred:

Traceback (most recent call last):
  File "/Users/Roho11/Documents/GitHub/DividendGrowthPicks/dividendStocks.py", line 76, in <module>
    div_stocks_data = get_snowball_analytics(stock_ids_file)
  File "/Users/Roho11/Documents/GitHub/DividendGrowthPicks/dividendStocks.py", line 43, in get_snowball_analytics
    response = requests.request("GET", url, data=payload, headers=headers, params=querystring)
  File "/Users/Roho11/opt/anaconda3/lib/python3.8/site-packages/requests/api.py", line 60, in request
    return session.request(method=method, url=url, **kwargs)
  File "/Users/Roho11/opt/anaconda3/lib/python3.8/site-packages/requests/sessions.py", line 533, in request
    resp = self.send(prep, **send_kwargs)
  File "/Users/Roho11/opt/anaconda3/lib/python3.8/site-packages/requests/sessions.py", line 646, in send
    r = adapter.send(request, **kwargs)
  File "/Users/Roho11/opt/anaconda3/lib/python3.8/site-packages/requests/adapters.py", line 498, in send
    raise ConnectionError(err, request=request)
requests.exceptions.ConnectionError: ('Connection aborted.', RemoteDisconnected('Remote end closed connection without response'))
